process[mycobot_services-1]: started with pid [23044]
[INFO] [1678411409.829512]: start ...
[INFO] [1678411409.837952]: /dev/ttyUSB0,115200
Traceback (most recent call last):
  File "/home/tyler/.local/lib/python3.8/site-packages/serial/serialposix.py", line 322, in open
    self.fd = os.open(self.portstr, os.O_RDWR | os.O_NOCTTY | os.O_NONBLOCK)
FileNotFoundError: [Errno 2] No such file or directory: '/dev/ttyUSB0'

During handling of the above exception, another exception occurred:

Traceback (most recent call last):
  File "/home/tyler/catkin_ws/devel/lib/mycobot_communication/mycobot_services.py", line 15, in <module>
    exec(compile(fh.read(), python_script, 'exec'), context)
  File "/home/tyler/catkin_ws/src/mycobot_ros/mycobot_communication/scripts/mycobot_services.py", line 207, in <module>
    create_handle()
  File "/home/tyler/catkin_ws/src/mycobot_ros/mycobot_communication/scripts/mycobot_services.py", line 59, in create_handle
    mc = MyCobot(port, baud)
  File "/home/tyler/.local/lib/python3.8/site-packages/pymycobot/mycobot.py", line 64, in __init__
    self._serial_port.open()
  File "/home/tyler/.local/lib/python3.8/site-packages/serial/serialposix.py", line 325, in open
    raise SerialException(msg.errno, "could not open port {}: {}".format(self._port, msg))
serial.serialutil.SerialException: [Errno 2] could not open port /dev/ttyUSB0: [Errno 2] No such file or directory: '/dev/ttyUSB0'
